[32m2024-07-30 21:50:45 -0500[0m - dagster - [34mDEBUG[0m - __ASSET_JOB - 04b5fde1-7295-4464-9aa8-eb5fc74f0658 - 21264 - LOGS_CAPTURED - Started capturing logs in process (pid: 21264).
[32m2024-07-30 21:50:45 -0500[0m - dagster - [34mDEBUG[0m - __ASSET_JOB - 04b5fde1-7295-4464-9aa8-eb5fc74f0658 - 21264 - embed_docs - STEP_START - Started execution of step "embed_docs".
[32m2024-07-30 21:50:45 -0500[0m - dagster - [34mDEBUG[0m - __ASSET_JOB - 04b5fde1-7295-4464-9aa8-eb5fc74f0658 - embed_docs - Loading file from: /Users/eliastavarez/Projects/indagxation/.dagster/storage/load_docs using PickledObjectFilesystemIOManager...
[32m2024-07-30 21:50:45 -0500[0m - dagster - [34mDEBUG[0m - __ASSET_JOB - 04b5fde1-7295-4464-9aa8-eb5fc74f0658 - 21264 - embed_docs - LOADED_INPUT - Loaded input "load_docs" using input manager "io_manager", from output "result" of step "load_docs"
[32m2024-07-30 21:50:45 -0500[0m - dagster - [34mDEBUG[0m - __ASSET_JOB - 04b5fde1-7295-4464-9aa8-eb5fc74f0658 - 21264 - embed_docs - STEP_INPUT - Got input "load_docs" of type "[Document]". (Type check passed).
[32m2024-07-30 21:50:45 -0500[0m - dagster - [34mERROR[0m - [31m__ASSET_JOB - 04b5fde1-7295-4464-9aa8-eb5fc74f0658 - 21264 - embed_docs - STEP_FAILURE - Execution of step "embed_docs" failed.

dagster._core.errors.DagsterExecutionStepExecutionError: Error occurred while executing op "embed_docs"::

Exception: Failed to embed documents into collection documents.

Stack Trace:
  File "/Users/eliastavarez/Projects/indagxation/.venv/lib/python3.11/site-packages/dagster/_core/execution/plan/utils.py", line 54, in op_execution_error_boundary
    yield
  File "/Users/eliastavarez/Projects/indagxation/.venv/lib/python3.11/site-packages/dagster/_utils/__init__.py", line 473, in iterate_with_context
    next_output = next(iterator)
                  ^^^^^^^^^^^^^^
  File "/Users/eliastavarez/Projects/indagxation/.venv/lib/python3.11/site-packages/dagster/_core/execution/plan/compute_generator.py", line 141, in _coerce_op_compute_fn_to_iterator
    result = invoke_compute_fn(
             ^^^^^^^^^^^^^^^^^^
  File "/Users/eliastavarez/Projects/indagxation/.venv/lib/python3.11/site-packages/dagster/_core/execution/plan/compute_generator.py", line 129, in invoke_compute_fn
    return fn(context, **args_to_pass) if context_arg_provided else fn(**args_to_pass)
                                                                    ^^^^^^^^^^^^^^^^^^
  File "/Users/eliastavarez/Projects/indagxation/indagxation/assets.py", line 23, in embed_docs
    chroma_client.embed_docs(_docs)
  File "/Users/eliastavarez/Projects/indagxation/indagxation/resources.py", line 36, in embed_docs
    raise Exception(f"Failed to embed documents into collection {self.default_collection}.") from e

The above exception was caused by the following exception:
ValueError: You must provide embeddings, documents, images, or uris.

Stack Trace:
  File "/Users/eliastavarez/Projects/indagxation/indagxation/resources.py", line 33, in embed_docs
    self._collection.add(docs)
  File "/Users/eliastavarez/Projects/indagxation/.venv/lib/python3.11/site-packages/chromadb/api/models/Collection.py", line 80, in add
    ) = self._validate_and_prepare_embedding_set(
        ^^^^^^^^^^^^^^^^^^^^^^^^^^^^^^^^^^^^^^^^^
  File "/Users/eliastavarez/Projects/indagxation/.venv/lib/python3.11/site-packages/chromadb/api/models/CollectionCommon.py", line 271, in _validate_and_prepare_embedding_set
    ) = self._validate_embedding_set(
        ^^^^^^^^^^^^^^^^^^^^^^^^^^^^^
  File "/Users/eliastavarez/Projects/indagxation/.venv/lib/python3.11/site-packages/chromadb/api/models/CollectionCommon.py", line 205, in _validate_embedding_set
    raise ValueError(
[0m
